<?xml version='1.0'?>
<robot xmlns:xacro="http://www.ros.org/wiki/xacro" name = "my_robot">
 <!--xacro:include filename="$(find my_robot)/src/urdf/hokuyo_utm30lx.urdf.xacro"/-->


        <link name="chassis">
            <pose xyz="0 0 0.1" rpy="0 0 0"/>
            <inertial>
             <mass value="15.0"/>
             <origin xyz="0.0 0 0.1" rpy=" 0 0 0"/>
              <inertia
               ixx="0.1" ixy="0" ixz="0"
               iyy="0.1" iyz="0"
               izz="0.1"
              />
            </inertial>

            <visual name='visual'>
              <geometry>
                <box size= "0.4 0.2 0.1"/>
              </geometry>
            </visual>

           <collision name='collision'>
              <geometry>
                <box size= "0.4 0.2 0.1"/>
              </geometry>
            </collision>
        </link>   

        <link name = "caster_wheel"> 
            <visual name='caster_visual'>
             <pose xyz="-0.15 0 -0.05" rpy="0 0 0"/>
              <geometry>
               <sphere radius="0.05"/>
              </geometry>
            </visual>

            <collision name='caster_collision'>
             <origin xyz="-0.15 0 -0.05" rpy=" 0 0 0"/>
              <geometry>
               <sphere radius="0.05"/>
              </geometry>
              <surface>
               <friction>
                <ode>
                 <mu>0</mu>
                 <mu2>0</mu2>
                 <slip1>1.0</slip1>
                 <slip2>1.0</slip2>
                </ode>
               </friction>
              </surface>
            </collision>   
        </link>

        <link name="left_wheel">
         <pose xyz="0.1 0.13 0.1" rpy="0 1.5707 1.5707"/>

         <inertial>
          <origin xyz="0 0 0" rpy="0 1.5707 1.5707"/>
          <mass value="5"/>
          <inertia
           ixx=".1" ixy="0.0" ixz="0.0"
           iyy=".1" iyz="0.0"
           izz=".1"/>
          </inertial>

          <visual name='visual'>
           <geometry>
            <cylinder radius="0.1" length="0.05"/>           
           </geometry>
          </visual>
                    
          <collision name='collision'>
           <geometry>
            <cylinder radius="0.1" length="0.05"/>
           </geometry>
          </collision>
        </link>
   
        <link name="right_wheel">
         <pose xyz="0.1 -0.13 0.1" rpy="0 1.5707 1.5707"/>
         <inertial>
          <origin xyz="0 0 0" rpy="0 1.5707 1.5707"/>
          <mass value="5"/>
          <inertia
           ixx=".1" ixy="0.0" ixz="0.0"
           iyy=".1" iyz="0.0"
           izz=".1"/>
          </inertial>

          <visual name='visual'>
           <geometry>
            <cylinder radius="0.1" length="0.05"/>
           </geometry>
          </visual>

          <collision name = 'collision'>
           <geometry>
            <cylinder radius="0.1" length="0.05"/>
           </geometry>
          </collision>
        </link>
   
        <joint name="caster_chassis" type="fixed">
          <parent link="chassis"/>
          <child link="caster_wheel"/>
          <axis xyz="0 0 1"/> 
        </joint>

        <joint name="left_wheel_hinge" type="continuous">
          <child link = "left_wheel"/>
          <parent link="chassis"/>
          <axis xyz="0 1 0"/>
          <pose xyz="0 0 -0.03" rpy="0 0 0"/>
          <limit effort="10000" velocity="1000"/>
          <joint_properties damping="1.0" friction="1.0"/>
        </joint>

        <joint name="right_wheel_hinge" type="continuous" >
          <child link = "right_wheel"/>
          <parent link ="chassis"/>
          <axis xyz="0 1 0"/>
          <pose xyz="0 0 0.03" rpy="0 0 0"/>
          <joint_properties damping="1.0" friction="1.0"/>
          <limit effort="10000" velocity="1000"/>
        </joint>
  
<!--hokuyo_utm30lx_model name="hokuyo_laser" parent="base_link">
    <origin xyz="0.2 0 0.2" rpy="0 0 0" />
  </hokuyo_utm30lx_model-->

        
        <!--include>
         <uri>model://hokuyo</uri>
          <pose>0.2 0 0.2 0 0 0</pose>
        </include-->
        <link name="hokuyo">
         <collision name = "collision">
          <origin xyz="0 0 0" rpy="0 0 0"/>
           <geometry>
            <box size="0.1 0.1 0.1"/>
           </geometry>
         </collision>

         <visual>
          <origin xyz="0 0 0" rpy="0 0 0"/>
           <geometry>
            <mesh filename="package://my_robot/src/meshes/hokuyo_utm30lx/hokuyo_utm30_lx.dae"/>
           </geometry>
         </visual>

            <inertial>
             <mass value="1e-5" />
             <origin xyz="0 0 0" rpy="0 0 0"/>
             <inertia ixx="1e-6" ixy="0" ixz="0" iyy="1e-6" iyz="0" izz="1e-6" />
            </inertial>
        </link>


    
        <joint name="hokuyo_joint" type="fixed">
         <child link ="hokuyo"/>
         <parent link ="chassis"/>
         <axis xyz="0 0 1"/>
         <origin xyz="0.2 0 0.2" rpy="0 0 0" />
        </joint>
</robot>
