<?xml version='1.0'?>
<robot name = "my_robot">
        <link name='chassis'>
            <!--origin xyz="0 0 0.1" rpy="0 0 0"/-->

            <visual name='visual'>
              <geometry>
                <box size= "0.4 0.2 0.1"/>
              </geometry>
            </visual>

            <collision>
              <geometry>
                <box size= "0.4 0.2 0.1"/>
              </geometry>
            </collision>

            <visual name='caster_visual'>
             <!--origin xyz="-0.15 0 -0.05" rpy="0 0 0"/-->
              <geometry>
               <sphere radius="0.05">
              </geometry>
            </visual>

            <collision>
             <!--origin xyz="-0.15 0 -0.05" rpy="0 0 0"/-->
              <geometry>
               <sphere radius="0.05">
              </geometry>
            </collision>

        </link>
        <link name="left_wheel">
         <!--origin xyz="0.1 0.13 0.1" rpy="0 1.5707 1.5707"/-->

          <visual name="visual">
           <geometry>
            <cylinder radius="0.1" length="0.05">           
           </geometry>
          </visual>
                    
          <collision>
           <geometry>
            <cylinder radius="0.1" length="0.05">
           </geometry>
          </collision>
          
        </link>
        <link name="right_wheel">
         <!--origin xyz="0.1 -0.13 0.1" rpy="0 1.5707 1.5707"/-->

          <visual name="visual">
           <geometry>
            <cylinder radius="0.1" length="0.05">
           </geometry>
          </visual>

          <collision>
           <geometry>
            <cylinder radius="0.1" length="0.05">
           </geometry>
          </collision>
        </link>
    
        <joint type="revolute" name="left_wheel_hinge">
          <child>left_wheel</child>
          <parent>chassis</parent>
          <axis xyz="0 1 0"/>
          <!--origin xyz="0 0 -0.03" rpy="0 0 0"/-->
        </joint>

        <joint type="revolute" name="right_wheel_hinge">
          <child>right_wheel</child>
          <parent>chassis</parent>
          <axis xyz="0 1 0"/>
          <!--origin xyz="0 0 0.03" rpy="0 0 0"/-->
        </joint>
    
        <include>
         <uri>model://hokuyo</uri>
          <pose>0.2 0 0.2 0 0 0</pose>
        </include>
    
        <joint name="hokuyo_joint" type="revolute">
         <child>hokuyo::link</child>
         <parent>chassis</parent>
         <axis xyz="0 0 1"/>
           <limit>
             <upper>0</upper>
             <lower>0</lower>
           </limit>
        </joint>
</robot>
